[2025-04-01T18:48:05.683+0000] {local_task_job_runner.py:123} INFO - ::group::Pre task execution logs
[2025-04-01T18:48:05.699+0000] {taskinstance.py:2614} INFO - Dependencies all met for dep_context=non-requeueable deps ti=<TaskInstance: run_ssis_python.execute_ssis_python manual__2025-04-01T18:48:02.376035+00:00 [queued]>
[2025-04-01T18:48:05.707+0000] {taskinstance.py:2614} INFO - Dependencies all met for dep_context=requeueable deps ti=<TaskInstance: run_ssis_python.execute_ssis_python manual__2025-04-01T18:48:02.376035+00:00 [queued]>
[2025-04-01T18:48:05.708+0000] {taskinstance.py:2867} INFO - Starting attempt 1 of 2
[2025-04-01T18:48:05.722+0000] {taskinstance.py:2890} INFO - Executing <Task(PythonOperator): execute_ssis_python> on 2025-04-01 18:48:02.376035+00:00
[2025-04-01T18:48:05.729+0000] {warnings.py:112} WARNING - /home/***/.local/lib/python3.12/site-packages/***/task/task_runner/standard_task_runner.py:70: DeprecationWarning: This process (pid=725) is multi-threaded, use of fork() may lead to deadlocks in the child.
  pid = os.fork()

[2025-04-01T18:48:05.730+0000] {standard_task_runner.py:104} INFO - Running: ['***', 'tasks', 'run', 'run_ssis_python', 'execute_ssis_python', 'manual__2025-04-01T18:48:02.376035+00:00', '--job-id', '162', '--raw', '--subdir', 'DAGS_FOLDER/ssis.py', '--cfg-path', '/tmp/tmpqgy65t0k']
[2025-04-01T18:48:05.731+0000] {standard_task_runner.py:72} INFO - Started process 726 to run task
[2025-04-01T18:48:05.732+0000] {standard_task_runner.py:105} INFO - Job 162: Subtask execute_ssis_python
[2025-04-01T18:48:05.819+0000] {task_command.py:467} INFO - Running <TaskInstance: run_ssis_python.execute_ssis_python manual__2025-04-01T18:48:02.376035+00:00 [running]> on host 44edad353d34
[2025-04-01T18:48:05.915+0000] {taskinstance.py:3134} INFO - Exporting env vars: AIRFLOW_CTX_DAG_OWNER='***' AIRFLOW_CTX_DAG_ID='run_ssis_python' AIRFLOW_CTX_TASK_ID='execute_ssis_python' AIRFLOW_CTX_EXECUTION_DATE='2025-04-01T18:48:02.376035+00:00' AIRFLOW_CTX_TRY_NUMBER='1' AIRFLOW_CTX_DAG_RUN_ID='manual__2025-04-01T18:48:02.376035+00:00'
[2025-04-01T18:48:05.916+0000] {taskinstance.py:732} INFO - ::endgroup::
[2025-04-01T18:48:05.959+0000] {logging_mixin.py:190} INFO - ‚ùå Error executing SSIS package: Command '"C:\Program Files\Microsoft SQL Server\160\DTS\Binn\dtexec" /F "C:\Users\Shehab\source\repos\***\Package.dtsx"' returned non-zero exit status 127.
[2025-04-01T18:48:05.960+0000] {python.py:240} INFO - Done. Returned value was: None
[2025-04-01T18:48:05.972+0000] {taskinstance.py:341} INFO - ::group::Post task execution logs
[2025-04-01T18:48:05.973+0000] {taskinstance.py:353} INFO - Marking task as SUCCESS. dag_id=run_ssis_python, task_id=execute_ssis_python, run_id=manual__2025-04-01T18:48:02.376035+00:00, execution_date=20250401T184802, start_date=20250401T184805, end_date=20250401T184805
[2025-04-01T18:48:06.039+0000] {local_task_job_runner.py:266} INFO - Task exited with return code 0
[2025-04-01T18:48:06.090+0000] {taskinstance.py:3901} INFO - 0 downstream tasks scheduled from follow-on schedule check
[2025-04-01T18:48:06.095+0000] {local_task_job_runner.py:245} INFO - ::endgroup::
