[2025-04-01T18:04:31.944+0000] {local_task_job_runner.py:123} INFO - ::group::Pre task execution logs
[2025-04-01T18:04:31.969+0000] {taskinstance.py:2614} INFO - Dependencies all met for dep_context=non-requeueable deps ti=<TaskInstance: run_ssis_python.execute_ssis_python scheduled__2025-03-31T00:00:00+00:00 [queued]>
[2025-04-01T18:04:31.980+0000] {taskinstance.py:2614} INFO - Dependencies all met for dep_context=requeueable deps ti=<TaskInstance: run_ssis_python.execute_ssis_python scheduled__2025-03-31T00:00:00+00:00 [queued]>
[2025-04-01T18:04:31.981+0000] {taskinstance.py:2867} INFO - Starting attempt 1 of 2
[2025-04-01T18:04:32.003+0000] {taskinstance.py:2890} INFO - Executing <Task(PythonOperator): execute_ssis_python> on 2025-03-31 00:00:00+00:00
[2025-04-01T18:04:32.012+0000] {warnings.py:112} WARNING - /home/***/.local/lib/python3.12/site-packages/***/task/task_runner/standard_task_runner.py:70: DeprecationWarning: This process (pid=174) is multi-threaded, use of fork() may lead to deadlocks in the child.
  pid = os.fork()

[2025-04-01T18:04:32.014+0000] {standard_task_runner.py:72} INFO - Started process 177 to run task
[2025-04-01T18:04:32.015+0000] {standard_task_runner.py:104} INFO - Running: ['***', 'tasks', 'run', 'run_ssis_python', 'execute_ssis_python', 'scheduled__2025-03-31T00:00:00+00:00', '--job-id', '159', '--raw', '--subdir', 'DAGS_FOLDER/ssis.py', '--cfg-path', '/tmp/tmp5kh3lmyl']
[2025-04-01T18:04:32.017+0000] {standard_task_runner.py:105} INFO - Job 159: Subtask execute_ssis_python
[2025-04-01T18:04:32.132+0000] {task_command.py:467} INFO - Running <TaskInstance: run_ssis_python.execute_ssis_python scheduled__2025-03-31T00:00:00+00:00 [running]> on host 44edad353d34
[2025-04-01T18:04:32.356+0000] {taskinstance.py:3134} INFO - Exporting env vars: AIRFLOW_CTX_DAG_OWNER='***' AIRFLOW_CTX_DAG_ID='run_ssis_python' AIRFLOW_CTX_TASK_ID='execute_ssis_python' AIRFLOW_CTX_EXECUTION_DATE='2025-03-31T00:00:00+00:00' AIRFLOW_CTX_TRY_NUMBER='1' AIRFLOW_CTX_DAG_RUN_ID='scheduled__2025-03-31T00:00:00+00:00'
[2025-04-01T18:04:32.357+0000] {taskinstance.py:732} INFO - ::endgroup::
[2025-04-01T18:04:33.034+0000] {logging_mixin.py:190} INFO - ‚ùå Error executing SSIS package: Command '"C:\Program Files\Microsoft SQL Server\160\DTS\Binn\dtexec" /F "C:\Users\Shehab\source\repos\***\Package.dtsx"' returned non-zero exit status 127.
[2025-04-01T18:04:33.035+0000] {python.py:240} INFO - Done. Returned value was: None
[2025-04-01T18:04:33.049+0000] {taskinstance.py:341} INFO - ::group::Post task execution logs
[2025-04-01T18:04:33.050+0000] {taskinstance.py:353} INFO - Marking task as SUCCESS. dag_id=run_ssis_python, task_id=execute_ssis_python, run_id=scheduled__2025-03-31T00:00:00+00:00, execution_date=20250331T000000, start_date=20250401T180431, end_date=20250401T180433
[2025-04-01T18:04:33.134+0000] {local_task_job_runner.py:266} INFO - Task exited with return code 0
[2025-04-01T18:04:33.145+0000] {local_task_job_runner.py:245} INFO - ::endgroup::
[2025-04-01T20:02:54.468+0000] {local_task_job_runner.py:123} INFO - ::group::Pre task execution logs
[2025-04-01T20:02:54.498+0000] {taskinstance.py:2614} INFO - Dependencies all met for dep_context=non-requeueable deps ti=<TaskInstance: run_ssis_python.execute_ssis_python scheduled__2025-03-31T00:00:00+00:00 [queued]>
[2025-04-01T20:02:54.505+0000] {taskinstance.py:2614} INFO - Dependencies all met for dep_context=requeueable deps ti=<TaskInstance: run_ssis_python.execute_ssis_python scheduled__2025-03-31T00:00:00+00:00 [queued]>
[2025-04-01T20:02:54.506+0000] {taskinstance.py:2867} INFO - Starting attempt 1 of 2
[2025-04-01T20:02:54.521+0000] {taskinstance.py:2890} INFO - Executing <Task(PythonOperator): execute_ssis_python> on 2025-03-31 00:00:00+00:00
[2025-04-01T20:02:54.527+0000] {warnings.py:112} WARNING - /home/***/.local/lib/python3.12/site-packages/***/task/task_runner/standard_task_runner.py:70: DeprecationWarning: This process (pid=104) is multi-threaded, use of fork() may lead to deadlocks in the child.
  pid = os.fork()

[2025-04-01T20:02:54.529+0000] {standard_task_runner.py:72} INFO - Started process 105 to run task
[2025-04-01T20:02:54.529+0000] {standard_task_runner.py:104} INFO - Running: ['***', 'tasks', 'run', 'run_ssis_python', 'execute_ssis_python', 'scheduled__2025-03-31T00:00:00+00:00', '--job-id', '177', '--raw', '--subdir', 'DAGS_FOLDER/ssis.py', '--cfg-path', '/tmp/tmp0rn8t7ac']
[2025-04-01T20:02:54.530+0000] {standard_task_runner.py:105} INFO - Job 177: Subtask execute_ssis_python
[2025-04-01T20:02:54.578+0000] {task_command.py:467} INFO - Running <TaskInstance: run_ssis_python.execute_ssis_python scheduled__2025-03-31T00:00:00+00:00 [running]> on host 9dc6feca7790
[2025-04-01T20:02:54.659+0000] {taskinstance.py:3134} INFO - Exporting env vars: AIRFLOW_CTX_DAG_OWNER='***' AIRFLOW_CTX_DAG_ID='run_ssis_python' AIRFLOW_CTX_TASK_ID='execute_ssis_python' AIRFLOW_CTX_EXECUTION_DATE='2025-03-31T00:00:00+00:00' AIRFLOW_CTX_TRY_NUMBER='1' AIRFLOW_CTX_DAG_RUN_ID='scheduled__2025-03-31T00:00:00+00:00'
[2025-04-01T20:02:54.661+0000] {taskinstance.py:732} INFO - ::endgroup::
[2025-04-01T20:02:54.686+0000] {taskinstance.py:3313} ERROR - Task failed with exception
Traceback (most recent call last):
  File "/home/airflow/.local/lib/python3.12/site-packages/airflow/models/taskinstance.py", line 768, in _execute_task
    result = _execute_callable(context=context, **execute_callable_kwargs)
             ^^^^^^^^^^^^^^^^^^^^^^^^^^^^^^^^^^^^^^^^^^^^^^^^^^^^^^^^^^^^^
  File "/home/airflow/.local/lib/python3.12/site-packages/airflow/models/taskinstance.py", line 734, in _execute_callable
    return ExecutionCallableRunner(
           ^^^^^^^^^^^^^^^^^^^^^^^^
  File "/home/airflow/.local/lib/python3.12/site-packages/airflow/utils/operator_helpers.py", line 252, in run
    return self.func(*args, **kwargs)
           ^^^^^^^^^^^^^^^^^^^^^^^^^^
  File "/home/airflow/.local/lib/python3.12/site-packages/airflow/models/baseoperator.py", line 424, in wrapper
    return func(self, *args, **kwargs)
           ^^^^^^^^^^^^^^^^^^^^^^^^^^^
  File "/home/airflow/.local/lib/python3.12/site-packages/airflow/operators/python.py", line 238, in execute
    return_value = self.execute_callable()
                   ^^^^^^^^^^^^^^^^^^^^^^^
  File "/home/airflow/.local/lib/python3.12/site-packages/airflow/operators/python.py", line 256, in execute_callable
    return runner.run(*self.op_args, **self.op_kwargs)
           ^^^^^^^^^^^^^^^^^^^^^^^^^^^^^^^^^^^^^^^^^^^
  File "/home/airflow/.local/lib/python3.12/site-packages/airflow/utils/operator_helpers.py", line 252, in run
    return self.func(*args, **kwargs)
           ^^^^^^^^^^^^^^^^^^^^^^^^^^
  File "/opt/airflow/dags/ssis.py", line 24, in run_ssis
    result = subprocess.run(ssis_command, shell=True, check=True, capture_output=True, text=True, cwd=ssis_path)
             ^^^^^^^^^^^^^^^^^^^^^^^^^^^^^^^^^^^^^^^^^^^^^^^^^^^^^^^^^^^^^^^^^^^^^^^^^^^^^^^^^^^^^^^^^^^^^^^^^^^
  File "/usr/local/lib/python3.12/subprocess.py", line 550, in run
    with Popen(*popenargs, **kwargs) as process:
         ^^^^^^^^^^^^^^^^^^^^^^^^^^^
  File "/usr/local/lib/python3.12/subprocess.py", line 1028, in __init__
    self._execute_child(args, executable, preexec_fn, close_fds,
  File "/usr/local/lib/python3.12/subprocess.py", line 1963, in _execute_child
    raise child_exception_type(errno_num, err_msg, err_filename)
FileNotFoundError: [Errno 2] No such file or directory: 'C:\\Program Files\\Microsoft SQL Server\\160\\DTS\\Binn'
[2025-04-01T20:02:54.706+0000] {taskinstance.py:1226} INFO - Marking task as UP_FOR_RETRY. dag_id=run_ssis_python, task_id=execute_ssis_python, run_id=scheduled__2025-03-31T00:00:00+00:00, execution_date=20250331T000000, start_date=20250401T200254, end_date=20250401T200254
[2025-04-01T20:02:54.736+0000] {taskinstance.py:341} INFO - ::group::Post task execution logs
[2025-04-01T20:02:54.738+0000] {standard_task_runner.py:124} ERROR - Failed to execute job 177 for task execute_ssis_python ([Errno 2] No such file or directory: 'C:\\Program Files\\Microsoft SQL Server\\160\\DTS\\Binn'; 105)
Traceback (most recent call last):
  File "/home/airflow/.local/lib/python3.12/site-packages/airflow/task/task_runner/standard_task_runner.py", line 117, in _start_by_fork
    ret = args.func(args, dag=self.dag)
          ^^^^^^^^^^^^^^^^^^^^^^^^^^^^^
  File "/home/airflow/.local/lib/python3.12/site-packages/airflow/cli/cli_config.py", line 49, in command
    return func(*args, **kwargs)
           ^^^^^^^^^^^^^^^^^^^^^
  File "/home/airflow/.local/lib/python3.12/site-packages/airflow/utils/cli.py", line 116, in wrapper
    return f(*args, **kwargs)
           ^^^^^^^^^^^^^^^^^^
  File "/home/airflow/.local/lib/python3.12/site-packages/airflow/cli/commands/task_command.py", line 483, in task_run
    task_return_code = _run_task_by_selected_method(args, _dag, ti)
                       ^^^^^^^^^^^^^^^^^^^^^^^^^^^^^^^^^^^^^^^^^^^^
  File "/home/airflow/.local/lib/python3.12/site-packages/airflow/cli/commands/task_command.py", line 256, in _run_task_by_selected_method
    return _run_raw_task(args, ti)
           ^^^^^^^^^^^^^^^^^^^^^^^
  File "/home/airflow/.local/lib/python3.12/site-packages/airflow/cli/commands/task_command.py", line 341, in _run_raw_task
    return ti._run_raw_task(
           ^^^^^^^^^^^^^^^^^
  File "/home/airflow/.local/lib/python3.12/site-packages/airflow/utils/session.py", line 97, in wrapper
    return func(*args, session=session, **kwargs)
           ^^^^^^^^^^^^^^^^^^^^^^^^^^^^^^^^^^^^^^
  File "/home/airflow/.local/lib/python3.12/site-packages/airflow/models/taskinstance.py", line 3006, in _run_raw_task
    return _run_raw_task(
           ^^^^^^^^^^^^^^
  File "/home/airflow/.local/lib/python3.12/site-packages/airflow/models/taskinstance.py", line 274, in _run_raw_task
    TaskInstance._execute_task_with_callbacks(
  File "/home/airflow/.local/lib/python3.12/site-packages/airflow/models/taskinstance.py", line 3161, in _execute_task_with_callbacks
    result = self._execute_task(context, task_orig)
             ^^^^^^^^^^^^^^^^^^^^^^^^^^^^^^^^^^^^^^
  File "/home/airflow/.local/lib/python3.12/site-packages/airflow/models/taskinstance.py", line 3185, in _execute_task
    return _execute_task(self, context, task_orig)
           ^^^^^^^^^^^^^^^^^^^^^^^^^^^^^^^^^^^^^^^
  File "/home/airflow/.local/lib/python3.12/site-packages/airflow/models/taskinstance.py", line 768, in _execute_task
    result = _execute_callable(context=context, **execute_callable_kwargs)
             ^^^^^^^^^^^^^^^^^^^^^^^^^^^^^^^^^^^^^^^^^^^^^^^^^^^^^^^^^^^^^
  File "/home/airflow/.local/lib/python3.12/site-packages/airflow/models/taskinstance.py", line 734, in _execute_callable
    return ExecutionCallableRunner(
           ^^^^^^^^^^^^^^^^^^^^^^^^
  File "/home/airflow/.local/lib/python3.12/site-packages/airflow/utils/operator_helpers.py", line 252, in run
    return self.func(*args, **kwargs)
           ^^^^^^^^^^^^^^^^^^^^^^^^^^
  File "/home/airflow/.local/lib/python3.12/site-packages/airflow/models/baseoperator.py", line 424, in wrapper
    return func(self, *args, **kwargs)
           ^^^^^^^^^^^^^^^^^^^^^^^^^^^
  File "/home/airflow/.local/lib/python3.12/site-packages/airflow/operators/python.py", line 238, in execute
    return_value = self.execute_callable()
                   ^^^^^^^^^^^^^^^^^^^^^^^
  File "/home/airflow/.local/lib/python3.12/site-packages/airflow/operators/python.py", line 256, in execute_callable
    return runner.run(*self.op_args, **self.op_kwargs)
           ^^^^^^^^^^^^^^^^^^^^^^^^^^^^^^^^^^^^^^^^^^^
  File "/home/airflow/.local/lib/python3.12/site-packages/airflow/utils/operator_helpers.py", line 252, in run
    return self.func(*args, **kwargs)
           ^^^^^^^^^^^^^^^^^^^^^^^^^^
  File "/opt/airflow/dags/ssis.py", line 24, in run_ssis
    result = subprocess.run(ssis_command, shell=True, check=True, capture_output=True, text=True, cwd=ssis_path)
             ^^^^^^^^^^^^^^^^^^^^^^^^^^^^^^^^^^^^^^^^^^^^^^^^^^^^^^^^^^^^^^^^^^^^^^^^^^^^^^^^^^^^^^^^^^^^^^^^^^^
  File "/usr/local/lib/python3.12/subprocess.py", line 550, in run
    with Popen(*popenargs, **kwargs) as process:
         ^^^^^^^^^^^^^^^^^^^^^^^^^^^
  File "/usr/local/lib/python3.12/subprocess.py", line 1028, in __init__
    self._execute_child(args, executable, preexec_fn, close_fds,
  File "/usr/local/lib/python3.12/subprocess.py", line 1963, in _execute_child
    raise child_exception_type(errno_num, err_msg, err_filename)
FileNotFoundError: [Errno 2] No such file or directory: 'C:\\Program Files\\Microsoft SQL Server\\160\\DTS\\Binn'
[2025-04-01T20:02:54.756+0000] {local_task_job_runner.py:266} INFO - Task exited with return code 1
[2025-04-01T20:02:54.774+0000] {taskinstance.py:3901} INFO - 0 downstream tasks scheduled from follow-on schedule check
[2025-04-01T20:02:54.778+0000] {local_task_job_runner.py:245} INFO - ::endgroup::
