[2025-03-28T11:19:20.964+0000] {local_task_job_runner.py:123} INFO - ::group::Pre task execution logs
[2025-03-28T11:19:20.991+0000] {taskinstance.py:2614} INFO - Dependencies all met for dep_context=non-requeueable deps ti=<TaskInstance: ssis_sql_to_sql.run_ssis_package scheduled__2025-03-27T00:00:00+00:00 [queued]>
[2025-03-28T11:19:21.003+0000] {taskinstance.py:2614} INFO - Dependencies all met for dep_context=requeueable deps ti=<TaskInstance: ssis_sql_to_sql.run_ssis_package scheduled__2025-03-27T00:00:00+00:00 [queued]>
[2025-03-28T11:19:21.004+0000] {taskinstance.py:2867} INFO - Starting attempt 1 of 2
[2025-03-28T11:19:21.028+0000] {taskinstance.py:2890} INFO - Executing <Task(BashOperator): run_ssis_package> on 2025-03-27 00:00:00+00:00
[2025-03-28T11:19:21.038+0000] {warnings.py:112} WARNING - /home/***/.local/lib/python3.12/site-packages/***/task/task_runner/standard_task_runner.py:70: DeprecationWarning: This process (pid=132) is multi-threaded, use of fork() may lead to deadlocks in the child.
  pid = os.fork()

[2025-03-28T11:19:21.042+0000] {standard_task_runner.py:72} INFO - Started process 134 to run task
[2025-03-28T11:19:21.042+0000] {standard_task_runner.py:104} INFO - Running: ['***', 'tasks', 'run', 'ssis_sql_to_sql', 'run_ssis_package', 'scheduled__2025-03-27T00:00:00+00:00', '--job-id', '136', '--raw', '--subdir', 'DAGS_FOLDER/ssis.py', '--cfg-path', '/tmp/tmpcs931vg1']
[2025-03-28T11:19:21.043+0000] {standard_task_runner.py:105} INFO - Job 136: Subtask run_ssis_package
[2025-03-28T11:19:21.135+0000] {task_command.py:467} INFO - Running <TaskInstance: ssis_sql_to_sql.run_ssis_package scheduled__2025-03-27T00:00:00+00:00 [running]> on host 1041ed642999
[2025-03-28T11:19:21.266+0000] {taskinstance.py:3134} INFO - Exporting env vars: AIRFLOW_CTX_DAG_OWNER='***' AIRFLOW_CTX_DAG_ID='ssis_sql_to_sql' AIRFLOW_CTX_TASK_ID='run_ssis_package' AIRFLOW_CTX_EXECUTION_DATE='2025-03-27T00:00:00+00:00' AIRFLOW_CTX_TRY_NUMBER='1' AIRFLOW_CTX_DAG_RUN_ID='scheduled__2025-03-27T00:00:00+00:00'
[2025-03-28T11:19:21.269+0000] {taskinstance.py:732} INFO - ::endgroup::
[2025-03-28T11:19:21.307+0000] {subprocess.py:78} INFO - Tmp dir root location: /tmp
[2025-03-28T11:19:21.309+0000] {subprocess.py:88} INFO - Running command: ['/usr/bin/bash', '-c', '"C:\\Program Files\\Microsoft SQL Server\\160\\DTS\\Binn\\dtexec.exe" /FILE "C:\\Users\\Shehab\\source\\repos\\mongo\\Package.dtsx"']
[2025-03-28T11:19:21.329+0000] {subprocess.py:99} INFO - Output:
[2025-03-28T11:19:21.361+0000] {subprocess.py:106} INFO - /usr/bin/bash: line 1: C:\Program Files\Microsoft SQL Server\160\DTS\Binn\dtexec.exe: command not found
[2025-03-28T11:19:21.362+0000] {subprocess.py:110} INFO - Command exited with return code 127
[2025-03-28T11:19:21.377+0000] {taskinstance.py:3313} ERROR - Task failed with exception
Traceback (most recent call last):
  File "/home/airflow/.local/lib/python3.12/site-packages/airflow/models/taskinstance.py", line 768, in _execute_task
    result = _execute_callable(context=context, **execute_callable_kwargs)
             ^^^^^^^^^^^^^^^^^^^^^^^^^^^^^^^^^^^^^^^^^^^^^^^^^^^^^^^^^^^^^
  File "/home/airflow/.local/lib/python3.12/site-packages/airflow/models/taskinstance.py", line 734, in _execute_callable
    return ExecutionCallableRunner(
           ^^^^^^^^^^^^^^^^^^^^^^^^
  File "/home/airflow/.local/lib/python3.12/site-packages/airflow/utils/operator_helpers.py", line 252, in run
    return self.func(*args, **kwargs)
           ^^^^^^^^^^^^^^^^^^^^^^^^^^
  File "/home/airflow/.local/lib/python3.12/site-packages/airflow/models/baseoperator.py", line 424, in wrapper
    return func(self, *args, **kwargs)
           ^^^^^^^^^^^^^^^^^^^^^^^^^^^
  File "/home/airflow/.local/lib/python3.12/site-packages/airflow/operators/bash.py", line 276, in execute
    raise AirflowException(
airflow.exceptions.AirflowException: Bash command failed. The command returned a non-zero exit code 127.
[2025-03-28T11:19:21.394+0000] {taskinstance.py:1226} INFO - Marking task as UP_FOR_RETRY. dag_id=ssis_sql_to_sql, task_id=run_ssis_package, run_id=scheduled__2025-03-27T00:00:00+00:00, execution_date=20250327T000000, start_date=20250328T111920, end_date=20250328T111921
[2025-03-28T11:19:21.452+0000] {taskinstance.py:341} INFO - ::group::Post task execution logs
[2025-03-28T11:19:21.453+0000] {standard_task_runner.py:124} ERROR - Failed to execute job 136 for task run_ssis_package (Bash command failed. The command returned a non-zero exit code 127.; 134)
Traceback (most recent call last):
  File "/home/airflow/.local/lib/python3.12/site-packages/airflow/task/task_runner/standard_task_runner.py", line 117, in _start_by_fork
    ret = args.func(args, dag=self.dag)
          ^^^^^^^^^^^^^^^^^^^^^^^^^^^^^
  File "/home/airflow/.local/lib/python3.12/site-packages/airflow/cli/cli_config.py", line 49, in command
    return func(*args, **kwargs)
           ^^^^^^^^^^^^^^^^^^^^^
  File "/home/airflow/.local/lib/python3.12/site-packages/airflow/utils/cli.py", line 116, in wrapper
    return f(*args, **kwargs)
           ^^^^^^^^^^^^^^^^^^
  File "/home/airflow/.local/lib/python3.12/site-packages/airflow/cli/commands/task_command.py", line 483, in task_run
    task_return_code = _run_task_by_selected_method(args, _dag, ti)
                       ^^^^^^^^^^^^^^^^^^^^^^^^^^^^^^^^^^^^^^^^^^^^
  File "/home/airflow/.local/lib/python3.12/site-packages/airflow/cli/commands/task_command.py", line 256, in _run_task_by_selected_method
    return _run_raw_task(args, ti)
           ^^^^^^^^^^^^^^^^^^^^^^^
  File "/home/airflow/.local/lib/python3.12/site-packages/airflow/cli/commands/task_command.py", line 341, in _run_raw_task
    return ti._run_raw_task(
           ^^^^^^^^^^^^^^^^^
  File "/home/airflow/.local/lib/python3.12/site-packages/airflow/utils/session.py", line 97, in wrapper
    return func(*args, session=session, **kwargs)
           ^^^^^^^^^^^^^^^^^^^^^^^^^^^^^^^^^^^^^^
  File "/home/airflow/.local/lib/python3.12/site-packages/airflow/models/taskinstance.py", line 3006, in _run_raw_task
    return _run_raw_task(
           ^^^^^^^^^^^^^^
  File "/home/airflow/.local/lib/python3.12/site-packages/airflow/models/taskinstance.py", line 274, in _run_raw_task
    TaskInstance._execute_task_with_callbacks(
  File "/home/airflow/.local/lib/python3.12/site-packages/airflow/models/taskinstance.py", line 3161, in _execute_task_with_callbacks
    result = self._execute_task(context, task_orig)
             ^^^^^^^^^^^^^^^^^^^^^^^^^^^^^^^^^^^^^^
  File "/home/airflow/.local/lib/python3.12/site-packages/airflow/models/taskinstance.py", line 3185, in _execute_task
    return _execute_task(self, context, task_orig)
           ^^^^^^^^^^^^^^^^^^^^^^^^^^^^^^^^^^^^^^^
  File "/home/airflow/.local/lib/python3.12/site-packages/airflow/models/taskinstance.py", line 768, in _execute_task
    result = _execute_callable(context=context, **execute_callable_kwargs)
             ^^^^^^^^^^^^^^^^^^^^^^^^^^^^^^^^^^^^^^^^^^^^^^^^^^^^^^^^^^^^^
  File "/home/airflow/.local/lib/python3.12/site-packages/airflow/models/taskinstance.py", line 734, in _execute_callable
    return ExecutionCallableRunner(
           ^^^^^^^^^^^^^^^^^^^^^^^^
  File "/home/airflow/.local/lib/python3.12/site-packages/airflow/utils/operator_helpers.py", line 252, in run
    return self.func(*args, **kwargs)
           ^^^^^^^^^^^^^^^^^^^^^^^^^^
  File "/home/airflow/.local/lib/python3.12/site-packages/airflow/models/baseoperator.py", line 424, in wrapper
    return func(self, *args, **kwargs)
           ^^^^^^^^^^^^^^^^^^^^^^^^^^^
  File "/home/airflow/.local/lib/python3.12/site-packages/airflow/operators/bash.py", line 276, in execute
    raise AirflowException(
airflow.exceptions.AirflowException: Bash command failed. The command returned a non-zero exit code 127.
[2025-03-28T11:19:21.500+0000] {local_task_job_runner.py:266} INFO - Task exited with return code 1
[2025-03-28T11:19:21.533+0000] {taskinstance.py:3901} INFO - 0 downstream tasks scheduled from follow-on schedule check
[2025-03-28T11:19:21.539+0000] {local_task_job_runner.py:245} INFO - ::endgroup::
